Workbook

Sheet Administracion
B3: en esta seccion que dice administracion solo has una tabla que muestre los datos de las otra tablas
B6: Bancos | C6: 10000
B7: Ingresos | C7: ='Consecutivo 2026'!H256 -> 0 | D7: Facturas por recibir pago.
C8: =C6+C7 -> 10000
B9: Gastos proveedores | C9: ='Pagos de la quincena'!P126 -> 324
C10: =C8-C9 -> 9676
B11: Gastos Ind. | C11: ='Pagos de la quincena'!P127 -> 670
C12: =C10-C11 -> 9006
B13: Nominas | C13: ='Pagos de la quincena'!P128 -> 0
C14: =C12-C13 -> 9006
B15: Impuestos | C15: ='Pagos de la quincena'!P129 -> 0
B16: TOTAL | C16: =C14-C15 -> 9006

Sheet Pagos de la quincena
B2: Folio | D2: Proveedor | E2: Fecha | F2: Servicio | G2: Sub total | H2: IVA | I2: Retencion 4% | J2: Retencion ISR | K2: Total | L2: P | M2: Folio | O2: OP
A3: 1 | D3: Jennifer | F3: Logistica | G3: 150 | H3: =G3*16% -> 24 | I3: 8 | J3: 8 | K3: =G3+H3-I3-J3 -> 158 | L3: P | M3: FE- | Q3: Tipos de folios que el sistema mostrara al usuario cuando el escriba las letras en la seccion Folio el sistema le mostrala o le ayudara a completar el folio
A4: =A3+1 -> 2 | D4: Jennifer | F4: Logistica | H4: =G4*16% -> 0 | K4: =G4+H4-I4-J4 -> 0 | L4: P | M4: FE- | Q4: FE- FLETE
A5: =A4+1 -> 3 | D5: Jennifer | F5: Logistica | G5: 150 | H5: =G5*16% -> 24 | I5: 8 | K5: =G5+H5-I5-J5 -> 166 | L5: P | M5: FE- | Q5: MA- MANIOBRA
A6: =A5+1 -> 4 | D6: Jennifer | F6: Logistica | H6: =G6*16% -> 0 | K6: =G6+H6-I6-J6 -> 0 | L6: P | M6: FE- | Q6: LA- LAVADO
A7: =A6+1 -> 5 | D7: Jennifer | F7: Logistica | H7: =G7*16% -> 0 | K7: =G7+H7-I7-J7 -> 0 | L7: P | M7: FE- | Q7: ES- ESTADIA
A8: =A7+1 -> 6 | D8: Jennifer | F8: Logistica | H8: =G8*16% -> 0 | K8: =G8+H8-I8-J8 -> 0 | L8: P | M8: FE- | Q8: DE-DEMORA
A9: =A7+1 -> 6 | D9: Jennifer | F9: Logistica | H9: =G9*16% -> 0 | K9: =G9+H9-I9-J9 -> 0 | L9: P | M9: FE-
A10: =A8+1 -> 7 | D10: Jennifer | F10: Logistica | H10: =G10*16% -> 0 | K10: =G10+H10-I10-J10 -> 0 | L10: P | M10: FE-
A11: 8 | D11: Jennifer | F11: Logistica | H11: =G11*16% -> 0 | K11: =G11+H11-I11-J11 -> 0 | L11: P | M11: FE-
A12: 9 | D12: Jennifer | F12: Logistica | H12: =G12*16% -> 0 | K12: =G12+H12-I12-J12 -> 0 | L12: P | M12: FE-
A13: 10 | D13: Jennifer | F13: Logistica | H13: =G13*16% -> 0 | K13: =G13+H13-I13-J13 -> 0 | L13: P | M13: FE-
A14: 11 | D14: Jennifer | F14: Logistica | H14: =G14*16% -> 0 | K14: =G14+H14-I14-J14 -> 0 | L14: P | M14: FE-
A15: 12 | D15: Jennifer | F15: Logistica | H15: =G15*16% -> 0 | K15: =G15+H15-I15-J15 -> 0 | L15: P | M15: FE-
A16: 13 | D16: Jennifer | F16: Logistica | H16: =G16*16% -> 0 | K16: =G16+H16-I16-J16 -> 0 | L16: P | M16: FE-
A17: 14 | D17: Jennifer | F17: Logistica | H17: =G17*16% -> 0 | K17: =G17+H17-I17-J17 -> 0 | L17: P | M17: FE-
A18: 15 | D18: Jennifer | F18: Logistica | H18: =G18*16% -> 0 | K18: =G18+H18-I18-J18 -> 0 | L18: P | M18: FE-
A19: 16 | D19: Jennifer | F19: Logistica | H19: =G19*16% -> 0 | K19: =G19+H19-I19-J19 -> 0 | L19: P | M19: FE-
G20: =SUMIF(L3:L19,"P",G3:G19) -> 300 | H20: =SUMIF(L3:L19,"P",H3:H19) -> 48 | I20: =SUMIF(L3:L19,"P",I3:I19) -> 16 | J20: =SUMIF(L3:L19,"P",J3:J19) -> 8 | K20: =SUMIF(L3:L19,"P",K3:K19) -> 324 | M20: todo lo mostrado en azul el sistema no deja que el usuario lo modifique ya que el sistema muestra el resultado
J21: .
B22: Folio | D22: Proveedor | E22: Fecha | F22: Servicio | G22: Sub total | H22: IVA | I22: Retencion 4% | J22: Retencion ISR | K22: Total | L22: P | M22: Folio | O22: OP
A23: =A22+1 -> 1 | B23: FF- | D23: Rama | H23: =G23*16% -> 0 | I23: =G23*4% -> 0 | J23: 0 | K23: =G23+H23-I23-J23 -> 0 | L23: P | M23: FE-
A24: =A23+1 -> 2 | B24: FF- | D24: Rama | H24: =G24*16% -> 0 | I24: =G24*4% -> 0 | J24: 0 | K24: =G24+H24-I24-J24 -> 0 | L24: P | M24: FE-
A25: =A24+1 -> 3 | B25: FF- | D25: Rama | H25: =G25*16% -> 0 | I25: =G25*4% -> 0 | J25: 0 | K25: =G25+H25-I25-J25 -> 0 | L25: P | M25: FE-
A26: =A25+1 -> 4 | B26: FF- | D26: Rama | H26: =G26*16% -> 0 | I26: 0 | J26: 0 | K26: =G26+H26-I26-J26 -> 0 | L26: P | M26: FE-
A27: =A26+1 -> 5 | B27: FF- | D27: Rama | H27: =G27*16% -> 0 | I27: 0 | J27: 0 | K27: =G27+H27-I27-J27 -> 0 | L27: P | M27: FE-
A28: =A27+1 -> 6 | B28: FF- | D28: Rama | H28: =G28*16% -> 0 | I28: =G28*4% -> 0 | J28: 0 | K28: =G28+H28-I28-J28 -> 0 | L28: P | M28: FE-
A29: =A28+1 -> 7 | B29: FF- | D29: Rama | H29: =G29*16% -> 0 | I29: =G29*4% -> 0 | J29: 0 | K29: =G29+H29-I29-J29 -> 0 | L29: P | M29: FE-
A30: =A29+1 -> 8 | B30: FF- | D30: Rama | H30: =G30*16% -> 0 | I30: 0 | J30: 0 | K30: =G30+H30-I30-J30 -> 0 | L30: P | M30: FE-
A31: =A30+1 -> 9 | B31: FF- | D31: Rama | H31: =G31*16% -> 0 | I31: 0 | J31: 0 | K31: =G31+H31-I31-J31 -> 0 | L31: P | M31: FE-
A32: =A31+1 -> 10 | B32: FF- | D32: Rama | H32: =G32*16% -> 0 | J32: 0 | K32: =G32+H32-I32-J32 -> 0 | L32: P | M32: FE-
A33: =A32+1 -> 11 | B33: FF- | D33: Rama | H33: =G33*16% -> 0 | J33: 0 | K33: =G33+H33-I33-J33 -> 0 | L33: P | M33: FE-
A34: =A33+1 -> 12 | B34: FF- | D34: Rama | H34: =G34*16% -> 0 | J34: 0 | K34: =G34+H34-I34-J34 -> 0 | L34: P | M34: FE-
A35: =A34+1 -> 13 | B35: FF- | D35: Rama | H35: =G35*16% -> 0 | J35: 0 | K35: =G35+H35-I35-J35 -> 0 | L35: P | M35: FE-
A36: =A35+1 -> 14 | B36: FF- | D36: Rama | H36: =G36*16% -> 0 | J36: 0 | K36: =G36+H36-I36-J36 -> 0 | L36: P | M36: FE-
A37: =A36+1 -> 15 | B37: FF- | D37: Rama | H37: =G37*16% -> 0 | J37: 0 | K37: =G37+H37-I37-J37 -> 0 | L37: P | M37: FE-
A38: =A37+1 -> 16 | B38: FF- | D38: Rama | H38: =G38*16% -> 0 | J38: 0 | K38: =G38+H38-I38-J38 -> 0 | L38: P | M38: FE-
A39: =A38+1 -> 17 | B39: FF- | D39: Rama | H39: =G39*16% -> 0 | J39: 0 | K39: =G39+H39-I39-J39 -> 0 | L39: P | M39: FE-
A40: =A39+1 -> 18 | B40: FF- | D40: Rama | H40: =G40*16% -> 0 | J40: 0 | K40: =G40+H40-I40-J40 -> 0 | L40: P | M40: FE-
A41: =A40+1 -> 19 | B41: FF- | D41: Rama | H41: =G41*16% -> 0 | J41: 0 | K41: =G41+H41-I41-J41 -> 0 | L41: P | M41: FE-
...

Sheet Consecutivo 2026
F1: RDP
A2: ENERO 26 | B2: Factura | C2: Fecha de emision | D2: Cliente | F2: Sub total | G2: IVA | H2: Total | I2: ST | J2: Fecha de pago | K2: Referencia OP | L2: Servicio | M2: Servicio | O2: % | P2: Rodipak | Q2: Hugo | R2: Hugo | S2: %
A3: 1 | B3: FE-196 | C3: 46024 | D3: Victor Hugo | E3: 945 | F3: 24720 | G3: =F3*16% -> 3955.2 | H3: =F3+G3 -> 28675.2 | I3: P | J3: 46037 | K3: RD2601001-F | L3: LOCAL CN | O3: =P3/F3 -> 0.27184466 | P3: 6720 | Q3: 1680 | R3: 26400 | S3: =Q3/R3 -> 0.063636364
A4: =A3+1 -> 2 | B4: FE-197 | C4: 46024 | D4: Victor Hugo | E4: 946 | F4: 68200 | G4: =F4*16% -> 10912 | H4: =F4+G4 -> 79112 | I4: P | J4: 46037 | K4: RD2601002-F | L4: Delivery | O4: =P4/F4 -> 0.061583578 | P4: 4200 | Q4: 1800 | R4: 70000 | S4: =Q4/R4 -> 0.025714286
A5: =A4+1 -> 3 | B5: FE-198 | C5: 46028 | D5: Victor Hugo | E5: 947 | F5: 3150 | G5: =F5*16% -> 504 | H5: =F5+G5 -> 3654 | I5: P | J5: 46037 | K5: RD2601-L | L5: Lavado CN | O5: =P5/F5 -> 0.14285714 | P5: 450 | Q5: 450 | R5: 3600 | S5: =Q5/R5 -> 0.125
A6: =A5+1 -> 4 | B6: FE-199 | C6: 46032 | D6: Victor Hugo | E6: 951 | F6: 70400 | G6: =F6*16% -> 11264 | H6: =F6+G6 -> 81664 | I6: P | J6: 46037 | K6: RD2601003-F | L6: Delivery | M6: Apodaca | O6: =P6/F6 -> 0.090909091 | P6: 6400 | Q6: 1600 | R6: 72000 | S6: =Q6/R6 -> 0.022222222
A7: =A6+1 -> 5 | B7: FE-200 | C7: 46032 | D7: Victor Hugo | E7: 952 | F7: 53400 | G7: =F7*16% -> 8544 | H7: =F7+G7 -> 61944 | I7: P | J7: 46037 | K7: RD2601004 | L7: Flete | M7: QRO | O7: =P7/F7 -> 0.11985019 | P7: 6400 | Q7: 1600 | R7: 55000 | S7: =Q7/R7 -> 0.029090909
A8: =A7+1 -> 6 | B8: FE-201 | C8: 46032 | D8: Victor Hugo | E8: 954 | F8: 6200 | G8: =F8*16% -> 992 | H8: =F8+G8 -> 7192 | I8: P | J8: 46037 | K8: RD2601003-F | L8: Peso extra | O8: =P8/F8 -> 0.19354839 | P8: 1200 | Q8: 300 | R8: 6500 | S8: =Q8/R8 -> 0.046153846
A9: =A8+1 -> 7 | B9: FE-202 | C9: 46032 | D9: Victor Hugo | E9: 955 | F9: 6200 | G9: =F9*16% -> 992 | H9: =F9+G9 -> 7192 | I9: P | J9: 46037 | K9: RD2601 | L9: Peso extra | O9: =P9/F9 -> 0.19354839 | P9: 1200 | Q9: 300 | R9: 6500 | S9: =Q9/R9 -> 0.046153846 | T9: =SUM(R3:R9) -> 240000 | U9: =T9*1.16 -> 278400
A10: =A9+1 -> 8 | B10: FE-203 | C10: 46032 | D10: Victor Hugo | E10: 958 | F10: 61800 | G10: =F10*16% -> 9888 | H10: =F10+G10 -> 71688 | I10: P | J10: 46052 | K10: RD2601005-F | L10: Flete | M10: Penstone | O10: =P10/F10 -> 0.077669903 | P10: 4800 | Q10: 1200 | R10: 63000 | S10: =Q10/R10 -> 0.019047619
A11: =A10+1 -> 9 | B11: FE-204 | C11: 46032 | D11: Victor Hugo | E11: 959 | F11: 61800 | G11: =F11*16% -> 9888 | H11: =F11+G11 -> 71688 | I11: P | J11: 46052 | K11: RD2601006-F | L11: Flete | M11: Penstone | O11: =P11/F11 -> 0.077669903 | P11: 4800 | Q11: 1200 | R11: 63000 | S11: =Q11/R11 -> 0.019047619
A12: =A11+1 -> 10 | B12: FE-205 | C12: 46032 | D12: Victor Hugo | E12: 961 | F12: 61800 | G12: =F12*16% -> 9888 | H12: =F12+G12 -> 71688 | I12: P | J12: 46052 | K12: RD2601007-F | L12: Flete | M12: Penstone | O12: =P12/F12 -> 0.077669903 | P12: 4800 | Q12: 1200 | R12: 63000 | S12: =Q12/R12 -> 0.019047619
A13: =A12+1 -> 11 | B13: FE-206 | C13: 46032 | D13: Victor Hugo | E13: 962 | F13: 40150 | G13: =F13*16% -> 6424 | H13: =F13+G13 -> 46574 | I13: P | J13: 46052 | K13: RD2601008-F | L13: Flete | M13: Penstone | O13: =P13/F13 -> 0.11955168 | P13: 4800 | Q13: 1200 | R13: 41500 | S13: =Q13/R13 -> 0.028915663
A14: =A13+1 -> 12 | B14: FE-207 | C14: 46032 | D14: Victor Hugo | E14: 963 | F14: 53800 | G14: =F14*16% -> 8608 | H14: =F14+G14 -> 62408 | I14: P | J14: 46052 | K14: RD2601009-F | L14: Flete | M14: SLP | O14: =P14/F14 -> 0.14498141 | P14: 7800 | Q14: 1200 | R14: 55000 | S14: =Q14/R14 -> 0.021818182
A15: =A14+1 -> 13 | B15: FE-208 | C15: 46035 | D15: Victor Hugo | E15: 943 | F15: 525 | G15: =F15*16% -> 84 | H15: =F15+G15 -> 609 | I15: P | J15: 46037 | L15: Lavado CN | O15: =P15/F15 -> 0.14285714 | P15: 75 | Q15: 75 | R15: 600 | S15: =Q15/R15 -> 0.125
A16: =A15+1 -> 14 | B16: FE-209 | C16: 46037 | D16: Victor Hugo | E16: 965 | F16: 2550 | G16: =F16*16% -> 408 | H16: =F16+G16 -> 2958 | I16: P | J16: 46052 | K16: RD2601012-F | L16: LOCAL CN | O16: =P16/F16 -> 0.1372549 | P16: 350 | Q16: 150 | R16: 2700 | S16: =Q16/R16 -> 0.055555556
A17: =A16+1 -> 15 | B17: FE-210 | C17: 46037 | D17: Victor Hugo | E17: 967 | F17: 3150 | G17: =F17*16% -> 504 | H17: =F17+G17 -> 3654 | I17: P | J17: 46052 | K17: RD260-L | L17: Lavado CN | O17: =P17/F17 -> 0.14285714 | P17: 450 | Q17: 450 | R17: 3600 | S17: =Q17/R17 -> 0.125
A18: =A17+1 -> 16 | B18: FE-211 | C18: 46037 | D18: Victor Hugo | E18: 968 | F18: 525 | G18: =F18*16% -> 84 | H18: =F18+G18 -> 609 | I18: P | J18: 46052 | K18: RD260-L | L18: Lavado CN | O18: =P18/F18 -> 0.14285714 | P18: 75 | Q18: 75 | R18: 600 | S18: =Q18/R18 -> 0.125
A19: =A18+1 -> 17 | B19: FE-212 | C19: 46037 | D19: Victor Hugo | E19: 971 | F19: 16480 | G19: =F19*16% -> 2636.8 | H19: =F19+G19 -> 19116.8 | I19: P | J19: 46052 | K19: RD260101011-F | L19: LOCAL CN | O19: =P19/F19 -> 0.27184466 | P19: 4480 | Q19: 1120 | R19: 17600 | S19: =Q19/R19 -> 0.063636364
A20: =A19+1 -> 18 | B20: FE-213 | C20: 46037 | D20: Victor Hugo | E20: 972 | F20: 17750 | G20: =F20*16% -> 2840 | H20: =F20+G20 -> 20590 | I20: P | J20: 46052 | K20: RD2601010-F | L20: Flete | O20: =P20/F20 -> 0.098591549 | P20: 1750 | Q20: 120 | R20: 18500 | S20: =Q20/R20 -> 0.0064864865
A21: =A20+1 -> 19 | B21: FE-214 | C21: 46038 | D21: Express | E21: NA | F21: 1000 | G21: =F21*16% -> 160 | H21: =F21+G21 -> 1160 | I21: P | J21: 46052 | K21: RET | L21: RET | O21: =P21/F21 -> 1 | P21: 1000 | Q21: 0 | R21: 0 | S21: =Q21/R21 -> #DIV/0!
A22: =A21+1 -> 20 | B22: FE-215 | C22: 46038 | D22: Victor Hugo | E22: 976 | F22: 4200 | G22: =F22*16% -> 672 | H22: =F22+G22 -> 4872 | I22: P | J22: 46052 | K22: RD2601013-L | L22: Lavado CN | O22: =P22/F22 -> 0.14285714 | P22: 600 | Q22: 600 | R22: 4800 | S22: =Q22/R22 -> 0.125
A23: =A22+1 -> 21 | B23: FE-216 | C23: Cancelado | D23: Cancelado | F23: 0 | G23: =F23*16% -> 0 | H23: =F23+G23 -> 0 | I23: P | J23: Cancelado | K23: Cancelado | L23: Cancelado | M23: Cancelado | O23: Cancelado | P23: Cancelado | Q23: Cancelado | R23: Cancelado | S23: Cancelado
A24: =A23+1 -> 22 | B24: FE-217 | C24: Cancelado | D24: Cancelado | F24: 0 | G24: =F24*16% -> 0 | H24: =F24+G24 -> 0 | I24: P | J24: Cancelado | K24: Cancelado | L24: Cancelado | M24: Cancelado | O24: Cancelado | P24: Cancelado | Q24: Cancelado | R24: Cancelado | S24: Cancelado
A25: =A24+1 -> 23 | B25: FE-218 | C25: 46042 | D25: Victor Hugo | E25: 978 | F25: 3150 | G25: =F25*16% -> 504 | H25: =F25+G25 -> 3654 | I25: P | J25: 46052 | K25: RD2601014-L | L25: Lavado CN | O25: =P25/F25 -> 0.14285714 | P25: 450 | Q25: 450 | R25: 3600 | S25: =Q25/R25 -> 0.125
A26: =A25+1 -> 24 | B26: FE-219 | C26: 46042 | D26: Victor Hugo | E26: 979 | F26: 1060 | G26: =F26*16% -> 169.6 | H26: =F26+G26 -> 1229.6 | I26: P | J26: 46052 | K26: RD2601015-L | L26: Lavado CN | O26: =P26/F26 -> 0.14150943 | P26: 150 | Q26: 150 | R26: 1200 | S26: =Q26/R26 -> 0.125
A27: =A26+1 -> 25 | B27: FE-220 | C27: 46043 | D27: Victor Hugo | E27: 983 | F27: 40375 | G27: =F27*16% -> 6460 | H27: =F27+G27 -> 46835 | I27: P | J27: 46052 | K27: RD2601015-F | L27: Flete | O27: =P27/F27 -> 0.083591331 | P27: 3375 | Q27: 1125 | R27: 41500 | S27: =Q27/R27 -> 0.027108434
A28: =A27+1 -> 26 | B28: FE-221 | C28: 46043 | D28: Victor Hugo | E28: 984 | F28: 67375 | G28: =F28*16% -> 10780 | H28: =F28+G28 -> 78155 | I28: P | J28: 46052 | K28: RD2601016-F | L28: Flete | O28: =P28/F28 -> 0.050092764 | P28: 3375 | Q28: 1125 | R28: 68500 | S28: =Q28/R28 -> 0.016423358
A29: =A28+1 -> 27 | B29: FE-222 | C29: 46044 | D29: Victor Hugo | E29: 986 | F29: 4130 | G29: =F29*16% -> 660.8 | H29: =F29+G29 -> 4790.8 | I29: P | J29: 46052 | K29: RD2601017-F | L29: LOCAL CN | O29: =P29/F29 -> 0.15254237 | P29: 630 | Q29: 270 | R29: 4400 | S29: =Q29/R29 -> 0.061363636
A30: =A29+1 -> 28 | B30: FE-223 | C30: Cancelado | D30: Cancelado | F30: 0 | G30: =F30*16% -> 0 | H30: =F30+G30 -> 0 | I30: P | J30: Cancelado | K30: Cancelado | L30: Cancelado | M30: Cancelado | O30: Cancelado | P30: Cancelado | Q30: Cancelado | R30: Cancelado | S30: Cancelado
A31: =A30+1 -> 29 | B31: FE-224 | C31: 46045 | D31: Victor Hugo | E31: 989 | F31: 23050 | G31: =F31*16% -> 3688 | H31: =F31+G31 -> 26738 | I31: P | J31: 46052 | K31: RD2601018-F | L31: FTL | M31: Caja seca | O31: =P31/F31 -> 0.045553145 | P31: 1050 | Q31: 450 | R31: 23500 | S31: =Q31/R31 -> 0.019148936
A32: =A31+1 -> 30 | B32: FE-225 | C32: 46045 | D32: Victor Hugo | E32: 990 | F32: 70400 | G32: =F32*16% -> 11264 | H32: =F32+G32 -> 81664 | I32: P | J32: 46052 | K32: RD2601019-F | L32: Flete | O32: =P32/F32 -> 0.090909091 | P32: 6400 | Q32: 1600 | R32: 72000 | S32: =Q32/R32 -> 0.022222222
A33: =A32+1 -> 31 | B33: FE-226 | C33: 46045 | D33: Victor Hugo | E33: 991 | F33: 6050 | G33: =F33*16% -> 968 | H33: =F33+G33 -> 7018 | I33: P | J33: 46052 | K33: ESTADIA | L33: Estadia | O33: =P33/F33 -> 0.17355372 | P33: 1050 | Q33: 450 | R33: 6500 | S33: =Q33/R33 -> 0.069230769
A34: =A33+1 -> 32 | B34: FE-227 | C34: 46046 | D34: Victor Hugo | E34: 992 | F34: 525 | G34: =F34*16% -> 84 | H34: =F34+G34 -> 609 | I34: P | J34: 46052 | K34: RD2601020-L | L34: Lavado CN | O34: =P34/F34 -> 0.14285714 | P34: 75 | Q34: 75 | R34: 600 | S34: =Q34/R34 -> 0.125
A35: =A34+1 -> 33 | B35: FE-228 | C35: 46049 | D35: Victor Hugo | E35: 994 | F35: 1050 | G35: =F35*16% -> 168 | H35: =F35+G35 -> 1218 | I35: P | J35: 46052 | K35: RD2621001-L | L35: Lavado CN | O35: =P35/F35 -> 0.14285714 | P35: 150 | Q35: 150 | R35: 1200 | S35: =Q35/R35 -> 0.125
A36: =A35+1 -> 34 | B36: FE-229 | C36: 46057 | D36: Victor Hugo | E36: 999 | F36: 13850 | G36: =F36*16% -> 2216 | H36: =F36+G36 -> 16066 | I36: P | J36: 46066 | K36: RDP2601021-F | L36: LOCAL CN | M36: 380-Jennifer | O36: =P36/F36 -> 0.20577617 | P36: 2850 | Q36: 850 | R36: 14700 | S36: =Q36/R36 -> 0.057823129
A37: =A36+1 -> 35 | B37: FE-230 | C37: 46057 | D37: Victor Hugo | E37: 1-102 | F37: 525 | G37: =F37*16% -> 84 | H37: =F37+G37 -> 609 | I37: P | J37: 46066 | K37: RDP2601001-L | L37: Lavado CN | M37: FF-311-Rama | O37: =P37/F37 -> 0.14285714 | P37: 75 | Q37: 75 | R37: 600 | S37: =Q37/R37 -> 0.125
A38: =A37+1 -> 36 | B38: FE-231 | C38: 46057 | D38: Victor Hugo | E38: 1-104 | F38: 1800 | G38: =F38*16% -> 288 | H38: =F38+G38 -> 2088 | I38: P | J38: 46066 | K38: RDP-2601002-L | L38: Lavado CN | M38: FF-312-Rama | O38: =P38/F38 -> 0.25 | P38: 450 | Q38: 0 | R38: 1800 | S38: =Q38/R38 -> 0
A39: =A38+1 -> 37 | B39: FE-232 | C39: 46057 | D39: N/A | E39: N/A | F39: 1200 | G39: =F39*16% -> 192 | H39: =F39+G39 -> 1392 | I39: P | J39: 46058 | K39: Express | L39: Express | M39: Express | O39: =P39/F39 -> 1 | P39: 1200 | Q39: 0 | R39: 0 | S39: 0
A40: =A39+1 -> 38 | B40: FE-233 | C40: 46057 | D40: Victor Hugo | E40: 1-107 | F40: 97000 | G40: =F40*16% -> 15520 | H40: =F40+G40 -> 112520 | I40: P | J40: 46066 | K40: RDP2602022-F | L40: Flete | M40: FF-315-Rama | O40: =P40/F40 -> 0.041237113 | P40: 4000 | Q40: 1000 | R40: 98000 | S40: =Q40/R40 -> 0.010204082
...

Sheet Hoja1
C3: FECHA DE QUINCENA
